规范中描述：如果出现异常，会自动调用reject方法，并将异常Exception实例作为参数传入
```js
// 将以下代码
executor(resolve, reject)

// 修改为如下代码
try {
  executor(resolve, reject)
} catch (e) {
  reject(e)
}
```

此时的代码

```js
const PENDING = 'PENDING'
const FULFILLED = 'FULFILLED'
const REJECTED = 'REJECTED'
class Promise {
  constructor (executor) {
    this.status = PENDING
    this.value = undefined
    this.reason = undefined
    const resolve = value => {
      if (this.status === PENDING) {
        this.status = FULFILLED
        this.value = value
      }
    }
    const reject = reason => {
      if (this.status === PENDING) {
        this.status = REJECTED
        this.reason = reason
      }
    }

    try {
      executor(resolve, reject)
    } catch (e) {
      reject(e)
    }
  }

  then (onFulfilled, onRejected) {
    if (this.status === FULFILLED) {
      onFulfilled(this.value)
    }
    if (this.status === REJECTED) {
      onRejected(this.reason)
    }
  }
}

module.exports = Promise
```