# 处理多次调用
PromiseA+规范中规定：resolve或reject方法只能调用一次，如果被调用多次，则只处理第一次调用，其余的都会被忽略。

我们实现的Promise库是符合这一规范的，但别人的Promise库不一定符合此规范，下面处理这一问题

我们的then方法中判断了当前Promise的状态，只要调用一次resolve或reject，Promise的状态就会发生变化，所以后面多次的调用都是无效的。

假设别人的Promise库叫做OtherPromise，我们来看如下代码：
```js
const Promise = require('./promise')
const OtherPromise = require('otherpromise')
const promise = new Promise((resolve, reject) => {
  resolve('成功了')
})

let promise2 = promise.then(value => {
  return new OtherPromise((resolve, reject) => {
    resolve('别人Promise库resolve第一次调用')
    resolve('别人Promise库resolve第二次调用')
  })
})

promise2.then(value => {
  console.log('value2', value) // 这里就有可能输出两次，不符合规范
})
```
我们定义一个Boolean变量called，用来标记resolve或者reject是否被调用过，初始值为false，只要调用过一次，就将called置为true，调用resolve或reject之前需要判断called是否为true，若为false则调用，反之无视
```js
const resolvePromise = (promise2, x, resolve, reject) => {
  if (x === promise2) {
    return reject(new TypeError('Chaining cycle detected for promise #<Promise></Promise>'))
  }

  let called = false
  if ((typeof x === 'object' && x !== null) || typeof x === 'function') {
    try {
      const then = x.then
      if (typeof then === 'function') {
        then.call(x, y => {
          if (called) {
            return
          }
          called = true
          resolvePromise(promise2, y, resolve, reject)
        }, r => {
          if (called) {
            return
          }
          called = true
          reject(r)
        })
      } else {
        resolve(x)
      }
    } catch (e) {
      if (called) {
        return
      }
      called = true
      reject(e)
    }
  } else {
    resolve(x)
  }
}
```
# 处理可选参数
PromiseA+规范规定：onFulfilled和onRejected都是可选参数
* 如果没传，则结果值会一直穿透，直到遇到提供了参数为止 

  ```js
  const promise = new Promise((resolve, reject) => {
    resolve('成功了')
  })

  promise.then().then().then(value => {
    console.log(value) // 成功了
  })
  ```

  ```js
  const Promise = require('./promise')

  const promise = new Promise((resolve, reject) => {
    reject('失败了')
  })

  promise.then().then().then(null, reason => {
    console.log(reason) // 失败了
  })
  ```
* 如果传入的参数不是一个函数，则忽略



```js
promise.then().then().then(value => {
  console.log(value) // 成功了
})
```

这个效果该如何实现呢？目前我们的代码是报错的，只不过错误被捕获了而已，因为第一个then中都没有传入回调函数，而代码中我们确调用了，那肯定是报错。

如果没有传入onFulfilled参数，我们的代码若能默认干如下的工作：提供一个函数，函数将结果值返回，这样就实现了该功能，就好比如下的使用方法就没有问题：
```js
promise.then(value => value).then(value => value).then(value => {
  console.log(value) // 成功了
})
```

所以总结一下：如果没传函数，那么我们就放一个这样的函数进去，并将结果值返回

```js
then (onFulfilled, onRejected) {
  onFulfilled = typeof onFulfilled === 'function' ? onFulfilled : value => value
  ...
}
```
接下来实现reject的情况

```js
promise.then().then().then(null, reason => {
  console.log(reason) // 失败了
})
```

上面这个效果又该如何实现呢？将代码改写为如下形式：

```js
promise.then(null, error => {
  throw error
}).then(null, error => {
  throw error
}).then(null, reason => {
  console.log(reason)
})
```

可以看到写成上面的形式就实现了，这就是原理，所以如果没有传入onRejected，那我们就放一个函数，并且该函数抛出结果值

```js
then (onFulfilled, onRejected) {
  onRejected = typeof onRejected === 'function' ? onRejected : reason => { throw reason }
  ...
}
```

# 处理resolve中嵌套Promise
```js
const Promise = require('./promise')

const promise = new Promise((resolve, reject) => {
  // resolve中又有一个Promise，我们最终拿到的应该是'ok'才对，而现在我们拿到的是整个Promise实例
  resolve(new Promise((resolve, reject) => {
    resolve('ok')
  }))
})
```

```js
class Promise {
  constructor (executor) {
    ...
    const resolve = value => {
      // 判断value是否为Promise
      if (value instanceof Promise) {
        return value.then(resolve, reject)
      }
      ...
    }
  }
}
```

至此Promise的核心功能以实现完毕，其它api的实现就相对简单了，下面贴出到目前为止的完整代码：
```js
const PENDING = 'PENDING'
const FULFILLED = 'FULFILLED'
const REJECTED = 'REJECTED'
const resolvePromise = (promise2, x, resolve, reject) => {
  if (x === promise2) { // 说明死循环了，直接拒绝即可
    return reject(new TypeError('Chaining cycle detected for promise #<Promise></Promise>'))
  }

  // 接下来 要判断x的类型  是普通值还是Promise

  let called = false
  if ((typeof x === 'object' && x !== null) || typeof x === 'function') {
    // 如何判断一个对象是否为Promise，换言之是否为thenable对象？只需判断对象是否拥有then方法即可，这也是thenable对象的定义
    try {
      const then = x.then // 获取then方法
      if (typeof then === 'function') { // 确保then是方法
        then.call(x, y => {
          if (called) {
            return
          }
          called = true
          // 递归解析y，直到保证它为一个普通值为止
          resolvePromise(promise2, y, resolve, reject)
        }, r => {
          if (called) {
            return
          }
          called = true
          reject(r)
        })
      } else { // then不是方法，则认为x是一个普通值，直接resolve(x)
        resolve(x)
      }
    } catch (e) {
      if (called) {
        return
      }
      called = true
      reject(e)
    }
  } else {
    // x是普通值
    resolve(x)
  }
}
class Promise {
  constructor (executor) {
    this.status = PENDING
    this.value = undefined
    this.reason = undefined

    this.onFulfilledCallbacks = [] // 存放成功回调函数
    this.onRejectedCallbacks = [] // 存放失败回调函数
    const resolve = value => {
      if (value instanceof Promise) {
        return value.then(resolve, reject)
      }
      if (this.status === PENDING) {
        this.status = FULFILLED
        this.value = value
        this.onFulfilledCallbacks.forEach(fn => fn())
      }
    }
    const reject = reason => {
      if (this.status === PENDING) {
        this.status = REJECTED
        this.reason = reason
        this.onRejectedCallbacks.forEach(fn => fn())
      }
    }

    try {
      executor(resolve, reject)
    } catch (e) {
      reject(e)
    }
  }

  then (onFulfilled, onRejected) {
    onFulfilled = typeof onFulfilled === 'function' ? onFulfilled : value => value
    onRejected = typeof onRejected === 'function' ? onRejected : reason => { throw reason }
    const promise2 = new Promise((resolve, reject) => {
      if (this.status === FULFILLED) {
        setTimeout(() => {
          try {
            const x = onFulfilled(this.value)
            resolvePromise(promise2, x, resolve, reject)
          } catch (e) {
            reject(e)
          }
        })
      }
      if (this.status === REJECTED) {
        setTimeout(() => {
          try {
            const x = onRejected(this.reason)
            resolvePromise(promise2, x, resolve, reject)
          } catch (e) {
            reject(e)
          }
        })
      }
  
      // 如果是pending状态，则说明存在异步代码，需要先将回调函数存放起来，等到resolve方法或reject方法被调用时，再依次调用
      if (this.status === PENDING) {
        this.onFulfilledCallbacks.push(() => {
          setTimeout(() => {
            try {
              const x = onFulfilled(this.value)
              resolvePromise(promise2, x, resolve, reject)
            } catch (e) {
              reject(e)
            }
          })
        })
        this.onRejectedCallbacks.push(() => {
          setTimeout(() => {
            try {
              const x = onRejected(this.reason)
              resolvePromise(promise2, x, resolve, reject)
            } catch (e) {
              reject(e)
            }
          })
        })
      }
    })
    return promise2
  }
}

module.exports = Promise
```