> 链式调用的核心实现原理：每次都返回一个新的Promise

Promise特性：

* then方法的两个参数，成功回调函数和失败回调函数都可以有返回值，并且可以返回任何值，包括返回一个Promise

  * 如果是一个普通值（只要不是异常，不是Promise，都叫普通值），会用这个值作为下一个then的成功回调函数的参数
  * 如果是一个Promise（thenable对象，具有then方法的对象被称为thenable对象），会用这个Promise的状态作为下一次then的结果
* 对错误的处理

  * 如果自己提供了捕获错误的方法-then方法的第二个失败回调参数或catch方法，那么这个错误就会向下传递
  * 如果自己没有提供，那错误会一直向下传递下去，直到遇到捕获错误的方法为止


下面让我们对then方法做以修改
```js
class Promise {
  then (onFulfilled, onRejected) {
    // 每次调用then都会产生一个新的Promise实例
    const promise2 = new Promise((resolve, reject) => {
      if (this.status === FULFILLED) {
        // 拿到成功回调函数执行的返回结果
        const x = onFulfilled(this.value)
        // 调用resolve方法，将返回结果传递给下一个then方法的成功回调函数
        resolve(x)
      }
      if (this.status === REJECTED) {
        onRejected(this.reason)
      }
  
      if (this.status === PENDING) {
        this.onFulfilledCallbacks.push(() => onFulfilled(this.value))
        this.onRejectedCallbacks.push(() => onRejected(this.reason))
      }
  
    })

    // 返回这个Promise实例
    return promise2
  }
}

module.exports = Promise
```
测试一下上面的改动
```js
const Promise = require('./promise')

const promise = new Promise((resolve, reject) => {
  resolve('成功了')
})

promise.then(value => {
  console.log('value1', value) // value1 成功了
  return 1000
}).then(value => {
  console.log('value2', value) // value2 1000
  return 2000
}).then(value => {
  console.log('value3', value) // value3 2000
})
```

可以看到已初步实现链式调用，上一次then中成功回调函数的返回值被作为参数传入了下一个then的成功回调函数，不过目前只实现了普通值的情况，如果出现错误或者返回一个Promise我们接下来实现

上面的返回结果我们没有做任何判断就直接传递给了下一个then，前面讨论过返回结果有三种可能：普通值、错误、thenable对象。所以需要写一个方法用来判断返回值的类型

值得注意的是返回值如果是一个Promise实例，那就有可能出现返回的是当前Promise实例的情况（使用者不小心写错了），这样就会出现循环调用，陷入死循环的困境，所以我们需要将promise2也一并传入，在方法中首先需要判断返回值x与当前的Promise实例是否为同一个，如果为同一个那就直接拒绝

判断完成之后，我们还需要做一系列的操作来最终决定是调用resolve还是reject，所以我们还需要将这两者也传入

综上可得，我们需要向方法传入四个参数：promise2、x、resolve、reject

```js
const resolvePromise = (promise2, x, resolve, reject) => {
  if (x === promise2) { // 说明死循环了，直接拒绝即可
    return reject(new TypeError('Chaining cycle detected for promise #<Promise></Promise>'))
  }
}
class Promise {
  then (onFulfilled, onRejected) {
    const promise2 = new Promise((resolve, reject) => {
      if (this.status === FULFILLED) {
        const x = onFulfilled(this.value)
        resolvePromise(promise2, x, resolve, reject)
      }
      if (this.status === REJECTED) {
        const x = onRejected(this.reason)
        resolvePromise(promise2, x, resolve, reject)
      }
  
      if (this.status === PENDING) {
        this.onFulfilledCallbacks.push(() => {
          const x = onFulfilled(this.value)
        })
        this.onRejectedCallbacks.push(() => {
          const x = onRejected(this.reason)
          resolvePromise(promise2, x, resolve, reject)
        })
      }
  
    })

    // 返回这个Promise实例
    return promise2
  }
}

module.exports = Promise
```

```js
const Promise = require('./promise')

const promise = new Promise((resolve, reject) => {
  resolve('成功了')
})

let promise2 = promise.then(value => {
  console.log('value1', value)
  return 1000
})

promise2.then(value => {
  console.log('value2', value)
  return 2000
})
```

测试一下发现，报`ReferenceError: promise2 is not defined`的错误，这是因为`const promise2 = new Promise((resolve, reject) => {...}`，需要等到executor中的代码执行完毕后，才会产生promise2实例，而executor中又存在`resolvePromise(promise2, x, resolve, reject)`这样一段代码，将promise2作为参数传给了resolvePromise方法，而此时promise2还没有被实例化完成，当然是undefined了。查看PromiseA+规范发现，官方明确指出了：”onFulfilled和onRejected方法不能在本次的事件循环中被执行，而应该在下一次的时间循环中被执行“，其实解决的就是我们遇到的错误。那如何让代码放到下次的事件循环中执行呢？最简单的办法就是将代码放入定时器中，将其变为异步代码，但异步代码如果报错是无法被try/catch捕获到的，所以我们还需要就近捕获异常，如果出现异常，就直接拒绝。
```js
then (onFulfilled, onRejected) {
  const promise2 = new Promise((resolve, reject) => {
    if (this.status === FULFILLED) {
      setTimeout(() => {
        try {
          const x = onFulfilled(this.value)
          resolvePromise(promise2, x, resolve, reject)
        } catch (e) {
          reject(e)
        }
      })
    }
    if (this.status === REJECTED) {
      setTimeout(() => {
        try {
          const x = onRejected(this.reason)
          resolvePromise(promise2, x, resolve, reject)
        } catch (e) {
          reject(e)
        }
      })
    }

    if (this.status === PENDING) {
      this.onFulfilledCallbacks.push(() => {
        setTimeout(() => {
          try {
            const x = onFulfilled(this.value)
            resolvePromise(promise2, x, resolve, reject)
          } catch (e) {
            reject(e)
          }
        })
      })
      this.onRejectedCallbacks.push(() => {
        setTimeout(() => {
          try {
            const x = onRejected(this.reason)
            resolvePromise(promise2, x, resolve, reject)
          } catch (e) {
            reject(e)
          }
        })
      })
    }

  })
  return promise2
}
```

以上then方法就处理完毕了，接下来工作的重点转移到resolvePromise这个方法中，我先将resolvePromise方法的全部代码贴出来，然后对其进行详尽分析
```js
const resolvePromise = (promise2, x, resolve, reject) => {
  if (x === promise2) { // 说明死循环了，直接拒绝即可
    return reject(new TypeError('Chaining cycle detected for promise #<Promise></Promise>'))
  }

  // 接下来 要判断x的类型  是普通值还是Promise
  if ((typeof x === 'object' && x !== null) || typeof x === 'function') {
    // 如何判断一个对象是否为Promise，换言之是否为thenable对象？只需判断对象是否拥有then方法即可，这也是thenable对象的定义
    try {
      const then = x.then // 获取then方法
      if (typeof then === 'function') { // 确保then是方法
        then.call(x, y => {
          resolve(y)
        }, r => {
          reject(r)
        })
      } else { // then不是方法，则认为x是一个普通值，直接resolve(x)
        resolve(x)
      }
    } catch (e) {
      reject(e)
    }
  } else {
    // x是普通值
    resolve(x)
  }
}
```
分析如下代码：
```js
if ((typeof x === 'object' && x !== null) || typeof x === 'function') {
  // 如何判断一个对象是否为Promise，换言之是否为thenable对象？只需判断对象是否拥有then方法即可，这也是thenable对象的定义
  try {
    const then = x.then // 获取then方法
    then.call(x, y => {
      resolve(y)
    }, r => {
      reject(r)
    })
  } catch (e) {
    reject(e)
  }
} else { // x是普通值
  resolve(x)
}
```

判断一个对象是否为thenable对象为什么不直接使用`x instanceof Promise`呢？这是因为PromiseA+规范中规定，我们的Promise有可能与别人家写的Promise混用，别人写的Promise名称不一定叫做Promise，所以我们只能判断对象是否为thenable对象，即判断是否具有then方法，而对象和函数都是有可能具有then方法的，故此处需要判断x的类型为对象或者为函数


`const then = x.then`获取then方法，获取then方法的时候可能会报错？获取方法怎么可能还会报错呢？请看下面代码
```js
Object.defineProperty('x', 'then', {
  get () {
    throw new Error('')
  }
})
```
诧异吧，如上的代码，在x.then的时候就会报错， PromiseA+规范为了严谨，于是说此处必须对可能出现的异常进行捕获


`then.call(x, ...)`为什么不直接`x.then(...)`呢？为什么要使用call方法调用呢？这是因为x.then相当于又获取了一次then方法，再次获取还是有可能报错，例如下面这段变态的代码：整一个计数器，在第二次被调用时出现了异常
```js
let idx = 0
Object.defineProperty('x', 'then', {
  get () {
    if (++idex === 2) {
      throw new Error('')
    }
  }
})
```

虽然这不大可能，但我们仍然需要处理，确保万无一失。所以此处使用了call方法来调用then，防止上述的情况发生

```js
then.call(x, y => {
  resolve(y)
}, r => {
  reject(r)
})
```

以上这段代码又是什么意思呢？我们写一段如下的测试代码来分析

```js
const Promise = require('./promise')

const promise = new Promise((resolve, reject) => {
  resolve('成功了')
})

let promise2 = promise.then(value => {
  return new Promise((resolve, reject) => {
    resolve('第二次成功了')
  })
})

promise2.then(value => {
  console.log('value2', value) // value2 第二次成功了
})
```

`then.call(x, y => {}, r => {})`相当于`x.then(onFulfilled, onRejected)`，其中`y=>{}`就是onFulfilled；`r=>{}`就是onRejected


当用户调用了`resolve('第二次成功了')`这段代码之后，onFulfilled回调函数就会被执行，即`y=>{}`执行，此时y就等于`第二次成功了`

`y => { resolve(y) }`onFulfilled回调函数被执行后我们调用了`resolve(y)`，这个resolve方法是promise2的，所以一调用resolve方法，promise2的onFulfilled回调函数就会被执行，即如下这段代码就会被执行

```js
promise2.then(value => {
  console.log('value2', value) // value2 第二次成功了
})
```
到目前为止resolvePromise方法基本都已经实现完毕，但有一种情况我们没有处理，请看如下代码：
```js
const Promise = require('./promise')

const promise = new Promise((resolve, reject) => {
  resolve('成功了')
})

let promise2 = promise.then(value => {
  return new Promise((resolve, reject) => {
    // 这里resolve方法中又传入了一个Promise实例
    resolve(new Promise((resolve, reject) => {
      resolve('ok')
    }))
  })
})

promise2.then(value => {
  // 原生的这里会输出：ok
  // 而我们写的这里会输出：new Promise(...)
  console.log(value)
})
```
为什么会出现和原生不一致的地方？这是因为`resolve(y)`这里我们没有对`y`进行判断，而是直接将其传给了下一个then，此处需要使用递归的思想去处理y：
```js
then.call(x, y => {
  // 递归解析y，直到保证它为一个普通值为止
  resolvePromise(promise2, y, resolve, reject)
}, r => {
  reject(r)
})
```

还有两个细节需要处理，请继续学习下一节



